Workbook

Sheet Summary
A1: The method to prepare the Ramp up Dashboard for a GCC Set up and track hiring, costs, projects etc
A2: Sheets we use here are:
A3: 1. Hiring info data (Raw Data) - should have any and all data for the hires, can be referred to in case of doubts or mismatches
B4: We further have a list to explain each variable in details
A5: 2. Ramp up Data (Raw Data Refined) - only variable that will be of use in the Dashboard
A6: 3. Refined view of all Roles, teams, Streams and any other level of granularity we might have (Roles) (Dimension Tables)
A7: 4. Stream, Team, Etc
A8: 5. Planned Ramp up data (Planned Demand)
A9: 6. HR metrics - Talent data for all hirees - skills, trainings, attrition, GallupQ, etc
A10: 7. Health Score - a summary score taken from executives on what the current status of health is for the GCC
B11: The summary needs to only be used for the current month, we can keep a separate history for all months prior, the data is used for current month only, and only latest data should be updated
A12: 8. Program trackers for different control towers to monitor overall progress on different fronts
A13: 9. Financial information - info on all the spend for the GCC, can have different parts - for ex. Fixed, labour, etc
B14: Financial Forecast - Variable spend for the GCC - labor spend
B15: Fixed spend - spend across Governance, Workplace Advisory and Real Estate (WARE), and Enterprise Strategy & Operational Blueprint (ESOB)
A17: Color codes-
A18: Red | B18: #FF0A0A
A19: Amber | B19: #FFAF3E
A20: Green | B20: #15AD5D
A21: Grey | B21: #E6E6E6
A22: Program Codes
A23: Green | B23: #ADEBAD
A24: Yellow | B24: #FCC578
A25: Red | B25: #F9A9A9

Sheet Raw Data
A1: CIDNo. | B1: Stream | C1: Stream Internal | D1: Team | E1: Role | F1: Client Side Role | G1: Skill | H1: Job Level | I1: Demand Date | J1: Candidate name | K1: Date Job Requirement Released | L1: Date Offered | M1: Date Onboarded | N1: Internal/External | O1: Pipeline Updated | P1: Candidate Stage | Q1: Role_IDP | R1: Role ID
A2: C0000001 | B2: Sales and Marketing | C2: SAM | D2: SalesTeam4 | E2: Brand Manager | F2: Brand Manager | G2: {=_xlfn.SWITCH(C2, "SAM", "Salesforce", "ITES","Jira", "ENGG","Python", "RND","Microsoft Platforms")} -> Salesforce | H2: =VLOOKUP(E2,Roles!$C$1:$D$197,2,FALSE) -> 7 | I2: 45878 | J2: Ben Grimm | K2: 45928 | N2: Internal | P2: Interviewing | Q2: =CONCATENATE(C2,"_",D2,"_",E2) -> SAM_SalesTeam4_Brand Manager | R2: =VLOOKUP(Q2,Roles!$A$2:$B$300,2,FALSE) -> 1
A3: C0000002 | B3: IT and Support | C3: ITES | D3: ITTeam5 | E3: System Administrator | F3: System Administrator | G3: {=_xlfn.SWITCH(C3, "SAM", "Salesforce", "ITES","Jira", "ENGG","Python", "RND","Microsoft Platforms")} -> Jira | H3: =VLOOKUP(E3,Roles!$C$1:$D$197,2,FALSE) -> 9 | I3: 45891 | J3: Jessica Jones | K3: 45947 | L3: 45962 | M3: 45975 | N3: Internal | O3: 2 | P3: Offered | Q3: =CONCATENATE(C3,"_",D3,"_",E3) -> ITES_ITTeam5_System Administrator | R3: =VLOOKUP(Q3,Roles!$A$2:$B$300,2,FALSE) -> 2
A4: C0000003 | B4: IT and Support | C4: ITES | D4: ITTeam5 | E4: IT Support Specialist | F4: IT Support Specialist | G4: {=_xlfn.SWITCH(C4, "SAM", "Salesforce", "ITES","Jira", "ENGG","Python", "RND","Microsoft Platforms")} -> Jira | H4: =VLOOKUP(E4,Roles!$C$1:$D$197,2,FALSE) -> 9 | I4: 45901 | J4: Danny Rand | K4: 45972 | N4: Internal | P4: Interviewing | Q4: =CONCATENATE(C4,"_",D4,"_",E4) -> ITES_ITTeam5_IT Support Specialist | R4: =VLOOKUP(Q4,Roles!$A$2:$B$300,2,FALSE) -> 3
A5: C0000004 | B5: Sales and Marketing | C5: SAM | D5: SalesTeam4 | E5: Sales Director | F5: Sales Director | G5: {=_xlfn.SWITCH(C5, "SAM", "Salesforce", "ITES","Jira", "ENGG","Python", "RND","Microsoft Platforms")} -> Salesforce | H5: =VLOOKUP(E5,Roles!$C$1:$D$197,2,FALSE) -> 4 | I5: 45889 | J5: Luke Cage | K5: 45963 | N5: Internal | P5: Interviewing | Q5: =CONCATENATE(C5,"_",D5,"_",E5) -> SAM_SalesTeam4_Sales Director | R5: =VLOOKUP(Q5,Roles!$A$2:$B$300,2,FALSE) -> 4
A6: C0000005 | B6: Engineering | C6: ENGG | D6: EngineeringTeam1 | E6: Platform Delivery Lead | F6: Platform Delivery Lead | G6: {=_xlfn.SWITCH(C6, "SAM", "Salesforce", "ITES","Jira", "ENGG","Python", "RND","Microsoft Platforms")} -> Python | H6: =VLOOKUP(E6,Roles!$C$1:$D$197,2,FALSE) -> 5 | I6: 45881 | J6: Bucky Barnes | K6: 45931 | N6: Internal | P6: Interviewing | Q6: =CONCATENATE(C6,"_",D6,"_",E6) -> ENGG_EngineeringTeam1_Platform Delivery Lead | R6: =VLOOKUP(Q6,Roles!$A$2:$B$300,2,FALSE) -> 5
A7: C0000006 | B7: Engineering | C7: ENGG | D7: EngineeringTeam10 | E7: Staff Engineer | F7: Staff Engineer | G7: {=_xlfn.SWITCH(C7, "SAM", "Salesforce", "ITES","Jira", "ENGG","Python", "RND","Microsoft Platforms")} -> Python | H7: =VLOOKUP(E7,Roles!$C$1:$D$197,2,FALSE) -> 11 | I7: 45926 | J7: Jessica Morales | K7: 45990 | N7: Internal | P7: Interviewing | Q7: =CONCATENATE(C7,"_",D7,"_",E7) -> ENGG_EngineeringTeam10_Staff Engineer | R7: =VLOOKUP(Q7,Roles!$A$2:$B$300,2,FALSE) -> 6
A8: C0000007 | B8: IT and Support | C8: ITES | D8: ITTeam2 | E8: Network Administrator | F8: Network Administrator | G8: {=_xlfn.SWITCH(C8, "SAM", "Salesforce", "ITES","Jira", "ENGG","Python", "RND","Microsoft Platforms")} -> Jira | H8: =VLOOKUP(E8,Roles!$C$1:$D$197,2,FALSE) -> 9 | I8: 45856 | J8: Gwen Stacy | K8: 45910 | L8: 45925 | M8: 45958 | N8: Internal | O8: 0 | P8: Offered | Q8: =CONCATENATE(C8,"_",D8,"_",E8) -> ITES_ITTeam2_Network Administrator | R8: =VLOOKUP(Q8,Roles!$A$2:$B$300,2,FALSE) -> 7
A9: C0000008 | B9: IT and Support | C9: ITES | D9: ITTeam1 | E9: System Administrator | F9: System Administrator | G9: {=_xlfn.SWITCH(C9, "SAM", "Salesforce", "ITES","Jira", "ENGG","Python", "RND","Microsoft Platforms")} -> Jira | H9: =VLOOKUP(E9,Roles!$C$1:$D$197,2,FALSE) -> 9 | I9: 45834 | J9: T'Challa Udaku | K9: 45900 | L9: 45912 | M9: 45999 | N9: Internal | O9: 0 | P9: Offered | Q9: =CONCATENATE(C9,"_",D9,"_",E9) -> ITES_ITTeam1_System Administrator | R9: =VLOOKUP(Q9,Roles!$A$2:$B$300,2,FALSE) -> 8
A10: C0000009 | B10: Engineering | C10: ENGG | D10: EngineeringTeam1 | E10: Software Developer 1 | F10: Software Developer 1 | G10: {=_xlfn.SWITCH(C10, "SAM", "Salesforce", "ITES","Jira", "ENGG","Python", "RND","Microsoft Platforms")} -> Python | H10: =VLOOKUP(E10,Roles!$C$1:$D$197,2,FALSE) -> 11 | I10: 45864 | J10: Kate Bishop | K10: 45931 | L10: 45946 | M10: 45972 | N10: Internal | O10: 2 | P10: Offered | Q10: =CONCATENATE(C10,"_",D10,"_",E10) -> ENGG_EngineeringTeam1_Software Developer 1 | R10: =VLOOKUP(Q10,Roles!$A$2:$B$300,2,FALSE) -> 9
A11: C0000010 | B11: Sales and Marketing | C11: SAM | D11: SalesTeam3 | E11: Sales Director | F11: Sales Director | G11: {=_xlfn.SWITCH(C11, "SAM", "Salesforce", "ITES","Jira", "ENGG","Python", "RND","Microsoft Platforms")} -> Salesforce | H11: =VLOOKUP(E11,Roles!$C$1:$D$197,2,FALSE) -> 4 | I11: 45904 | J11: Kate Cage | K11: 45959 | L11: 45975 | M11: 46007 | N11: Internal | O11: 2 | P11: Offered | Q11: =CONCATENATE(C11,"_",D11,"_",E11) -> SAM_SalesTeam3_Sales Director | R11: =VLOOKUP(Q11,Roles!$A$2:$B$300,2,FALSE) -> 10
A12: C0000011 | B12: Sales and Marketing | C12: SAM | D12: SalesTeam5 | E12: Sales Director | F12: Sales Director | G12: {=_xlfn.SWITCH(C12, "SAM", "Salesforce", "ITES","Jira", "ENGG","Python", "RND","Microsoft Platforms")} -> Salesforce | H12: =VLOOKUP(E12,Roles!$C$1:$D$197,2,FALSE) -> 4 | I12: 45872 | J12: Luke Maximoff | K12: 45942 | L12: 45955 | M12: 46016 | N12: Internal | O12: 0 | P12: Offered | Q12: =CONCATENATE(C12,"_",D12,"_",E12) -> SAM_SalesTeam5_Sales Director | R12: =VLOOKUP(Q12,Roles!$A$2:$B$300,2,FALSE) -> 11
A13: C0000012 | B13: IT and Support | C13: ITES | D13: ITTeam6 | E13: System Administrator | F13: System Administrator | G13: {=_xlfn.SWITCH(C13, "SAM", "Salesforce", "ITES","Jira", "ENGG","Python", "RND","Microsoft Platforms")} -> Jira | H13: =VLOOKUP(E13,Roles!$C$1:$D$197,2,FALSE) -> 9 | I13: 45927 | J13: Luke Khan | K13: 45994 | N13: Internal | P13: Interviewing | Q13: =CONCATENATE(C13,"_",D13,"_",E13) -> ITES_ITTeam6_System Administrator | R13: =VLOOKUP(Q13,Roles!$A$2:$B$300,2,FALSE) -> 12
A14: C0000013 | B14: Sales and Marketing | C14: SAM | D14: SalesTeam8 | E14: Digital Marketing Specialist | F14: Digital Marketing Specialist | G14: {=_xlfn.SWITCH(C14, "SAM", "Salesforce", "ITES","Jira", "ENGG","Python", "RND","Microsoft Platforms")} -> Salesforce | H14: =VLOOKUP(E14,Roles!$C$1:$D$197,2,FALSE) -> 10 | I14: 45888 | J14: Logan Howlett | K14: 45955 | L14: 45966 | M14: 46053 | N14: Internal | O14: 1 | P14: Offered | Q14: =CONCATENATE(C14,"_",D14,"_",E14) -> SAM_SalesTeam8_Digital Marketing Specialist | R14: =VLOOKUP(Q14,Roles!$A$2:$B$300,2,FALSE) -> 13
A15: C0000014 | B15: Research | C15: RND | D15: ResearchTeam8 | E15: Innovation Manager | F15: Innovation Manager | G15: {=_xlfn.SWITCH(C15, "SAM", "Salesforce", "ITES","Jira", "ENGG","Python", "RND","Microsoft Platforms")} -> Microsoft Platforms | H15: =VLOOKUP(E15,Roles!$C$1:$D$197,2,FALSE) -> 8 | I15: 45823 | J15: Natasha Romanoff | K15: 45877 | L15: 45895 | M15: 45913 | N15: Internal | O15: 0 | P15: Offered | Q15: =CONCATENATE(C15,"_",D15,"_",E15) -> RND_ResearchTeam8_Innovation Manager | R15: =VLOOKUP(Q15,Roles!$A$2:$B$300,2,FALSE) -> 14
A16: C0000015 | B16: Sales and Marketing | C16: SAM | D16: SalesTeam5 | E16: Brand Manager | F16: Brand Manager | G16: {=_xlfn.SWITCH(C16, "SAM", "Salesforce", "ITES","Jira", "ENGG","Python", "RND","Microsoft Platforms")} -> Salesforce | H16: =VLOOKUP(E16,Roles!$C$1:$D$197,2,FALSE) -> 7 | I16: 45925 | J16: Jean Grey | K16: 45988 | L16: 45999 | M16: 46052 | N16: Internal | O16: 2 | P16: Offered | Q16: =CONCATENATE(C16,"_",D16,"_",E16) -> SAM_SalesTeam5_Brand Manager | R16: =VLOOKUP(Q16,Roles!$A$2:$B$300,2,FALSE) -> 15
A17: C0000016 | B17: IT and Support | C17: ITES | D17: ITTeam9 | E17: System Administrator | F17: System Administrator | G17: {=_xlfn.SWITCH(C17, "SAM", "Salesforce", "ITES","Jira", "ENGG","Python", "RND","Microsoft Platforms")} -> Jira | H17: =VLOOKUP(E17,Roles!$C$1:$D$197,2,FALSE) -> 9 | I17: 45840 | J17: Matt Murdock | K17: 45887 | N17: Internal | P17: Interviewing | Q17: =CONCATENATE(C17,"_",D17,"_",E17) -> ITES_ITTeam9_System Administrator | R17: =VLOOKUP(Q17,Roles!$A$2:$B$300,2,FALSE) -> 16
A18: C0000017 | B18: IT and Support | C18: ITES | D18: ITTeam3 | E18: Technical Support Analyst | F18: Technical Support Analyst | G18: {=_xlfn.SWITCH(C18, "SAM", "Salesforce", "ITES","Jira", "ENGG","Python", "RND","Microsoft Platforms")} -> Jira | H18: =VLOOKUP(E18,Roles!$C$1:$D$197,2,FALSE) -> 11 | I18: 45862 | J18: Hal Jordan | K18: 45929 | L18: 45939 | M18: 46009 | N18: Internal | O18: 2 | P18: Offered | Q18: =CONCATENATE(C18,"_",D18,"_",E18) -> ITES_ITTeam3_Technical Support Analyst | R18: =VLOOKUP(Q18,Roles!$A$2:$B$300,2,FALSE) -> 17
A19: C0000018 | B19: IT and Support | C19: ITES | D19: ITTeam10 | E19: Technical Support Analyst | F19: Technical Support Analyst | G19: {=_xlfn.SWITCH(C19, "SAM", "Salesforce", "ITES","Jira", "ENGG","Python", "RND","Microsoft Platforms")} -> Jira | H19: =VLOOKUP(E19,Roles!$C$1:$D$197,2,FALSE) -> 11 | I19: 45921 | J19: Gwen Bishop | K19: 45989 | L19: 46007 | M19: 46016 | N19: Internal | O19: 1 | P19: Offered | Q19: =CONCATENATE(C19,"_",D19,"_",E19) -> ITES_ITTeam10_Technical Support Analyst | R19: =VLOOKUP(Q19,Roles!$A$2:$B$300,2,FALSE) -> 18
A20: C0000019 | B20: Research | C20: RND | D20: ResearchTeam9 | E20: Research Analyst | F20: Research Analyst | G20: {=_xlfn.SWITCH(C20, "SAM", "Salesforce", "ITES","Jira", "ENGG","Python", "RND","Microsoft Platforms")} -> Microsoft Platforms | H20: =VLOOKUP(E20,Roles!$C$1:$D$197,2,FALSE) -> 11 | I20: 45919 | J20: T'Challa Prince | K20: 45988 | L20: 45999 | M20: 46007 | N20: Internal | O20: 2 | P20: Offered | Q20: =CONCATENATE(C20,"_",D20,"_",E20) -> RND_ResearchTeam9_Research Analyst | R20: =VLOOKUP(Q20,Roles!$A$2:$B$300,2,FALSE) -> 19
A21: C0000020 | B21: Research | C21: RND | D21: ResearchTeam7 | E21: Research Analyst | F21: Research Analyst | G21: {=_xlfn.SWITCH(C21, "SAM", "Salesforce", "ITES","Jira", "ENGG","Python", "RND","Microsoft Platforms")} -> Microsoft Platforms | H21: =VLOOKUP(E21,Roles!$C$1:$D$197,2,FALSE) -> 11 | I21: 45907 | J21: Scott Lang | K21: 45952 | N21: Internal | P21: Interviewing | Q21: =CONCATENATE(C21,"_",D21,"_",E21) -> RND_ResearchTeam7_Research Analyst | R21: =VLOOKUP(Q21,Roles!$A$2:$B$300,2,FALSE) -> 20
A22: C0000021 | B22: Sales and Marketing | C22: SAM | D22: SalesTeam6 | E22: Sales Director | F22: Sales Director | G22: {=_xlfn.SWITCH(C22, "SAM", "Salesforce", "ITES","Jira", "ENGG","Python", "RND","Microsoft Platforms")} -> Salesforce | H22: =VLOOKUP(E22,Roles!$C$1:$D$197,2,FALSE) -> 4 | I22: 45871 | J22: Carol Danvers | K22: 45940 | L22: 45960 | M22: 45967 | N22: Internal | O22: 0 | P22: Offered | Q22: =CONCATENATE(C22,"_",D22,"_",E22) -> SAM_SalesTeam6_Sales Director | R22: =VLOOKUP(Q22,Roles!$A$2:$B$300,2,FALSE) -> 21
A23: C0000022 | B23: Research | C23: RND | D23: ResearchTeam3 | E23: Research Analyst | F23: Research Analyst | G23: {=_xlfn.SWITCH(C23, "SAM", "Salesforce", "ITES","Jira", "ENGG","Python", "RND","Microsoft Platforms")} -> Microsoft Platforms | H23: =VLOOKUP(E23,Roles!$C$1:$D$197,2,FALSE) -> 11 | I23: 45845 | J23: Bruce Banner | K23: 45903 | L23: 45917 | M23: 45971 | N23: Internal | O23: 1 | P23: Offered | Q23: =CONCATENATE(C23,"_",D23,"_",E23) -> RND_ResearchTeam3_Research Analyst | R23: =VLOOKUP(Q23,Roles!$A$2:$B$300,2,FALSE) -> 22
A24: C0000023 | B24: IT and Support | C24: ITES | D24: ITTeam4 | E24: Application Support Analyst | F24: Application Support Analyst | G24: {=_xlfn.SWITCH(C24, "SAM", "Salesforce", "ITES","Jira", "ENGG","Python", "RND","Microsoft Platforms")} -> Jira | H24: =VLOOKUP(E24,Roles!$C$1:$D$197,2,FALSE) -> 11 | I24: 45900 | J24: Arthur Curry | K24: 45955 | N24: Internal | P24: Interviewing | Q24: =CONCATENATE(C24,"_",D24,"_",E24) -> ITES_ITTeam4_Application Support Analyst | R24: =VLOOKUP(Q24,Roles!$A$2:$B$300,2,FALSE) -> 23
A25: C0000024 | B25: Engineering | C25: ENGG | D25: EngineeringTeam5 | E25: Engineering Manager | F25: Engineering Manager | G25: {=_xlfn.SWITCH(C25, "SAM", "Salesforce", "ITES","Jira", "ENGG","Python", "RND","Microsoft Platforms")} -> Python | H25: =VLOOKUP(E25,Roles!$C$1:$D$197,2,FALSE) -> 7 | I25: 45869 | J25: Luke Grey | K25: 45918 | N25: Internal | P25: Interviewing | Q25: =CONCATENATE(C25,"_",D25,"_",E25) -> ENGG_EngineeringTeam5_Engineering Manager | R25: =VLOOKUP(Q25,Roles!$A$2:$B$300,2,FALSE) -> 24
A26: C0000025 | B26: Sales and Marketing | C26: SAM | D26: SalesTeam2 | E26: Sales Manager | F26: Sales Manager | G26: {=_xlfn.SWITCH(C26, "SAM", "Salesforce", "ITES","Jira", "ENGG","Python", "RND","Microsoft Platforms")} -> Salesforce | H26: =VLOOKUP(E26,Roles!$C$1:$D$197,2,FALSE) -> 7 | I26: 45878 | J26: Natasha Wilson | K26: 45932 | L26: 45947 | M26: 46025 | N26: Internal | O26: 1 | P26: Offered | Q26: =CONCATENATE(C26,"_",D26,"_",E26) -> SAM_SalesTeam2_Sales Manager | R26: =VLOOKUP(Q26,Roles!$A$2:$B$300,2,FALSE) -> 25
A27: C0000026 | B27: Engineering | C27: ENGG | D27: EngineeringTeam10 | E27: Staff Engineer | F27: Staff Engineer | G27: {=_xlfn.SWITCH(C27, "SAM", "Salesforce", "ITES","Jira", "ENGG","Python", "RND","Microsoft Platforms")} -> Python | H27: =VLOOKUP(E27,Roles!$C$1:$D$197,2,FALSE) -> 11 | I27: 45815 | J27: Ben Storm | K27: 45885 | N27: Internal | P27: Interviewing | Q27: =CONCATENATE(C27,"_",D27,"_",E27) -> ENGG_EngineeringTeam10_Staff Engineer | R27: =VLOOKUP(Q27,Roles!$A$2:$B$300,2,FALSE) -> 6
A28: C0000027 | B28: Research | C28: RND | D28: ResearchTeam7 | E28: Research Analyst | F28: Research Analyst | G28: {=_xlfn.SWITCH(C28, "SAM", "Salesforce", "ITES","Jira", "ENGG","Python", "RND","Microsoft Platforms")} -> Microsoft Platforms | H28: =VLOOKUP(E28,Roles!$C$1:$D$197,2,FALSE) -> 11 | I28: 45831 | J28: Charles Xavier | K28: 45899 | L28: 45913 | M28: 45966 | N28: Internal | O28: 2 | P28: Offered | Q28: =CONCATENATE(C28,"_",D28,"_",E28) -> RND_ResearchTeam7_Research Analyst | R28: =VLOOKUP(Q28,Roles!$A$2:$B$300,2,FALSE) -> 20
A29: C0000028 | B29: Sales and Marketing | C29: SAM | D29: SalesTeam2 | E29: Digital Marketing Specialist | F29: Digital Marketing Specialist | G29: {=_xlfn.SWITCH(C29, "SAM", "Salesforce", "ITES","Jira", "ENGG","Python", "RND","Microsoft Platforms")} -> Salesforce | H29: =VLOOKUP(E29,Roles!$C$1:$D$197,2,FALSE) -> 10 | I29: 45929 | J29: Diana Prince | K29: 46000 | N29: Internal | P29: Interviewing | Q29: =CONCATENATE(C29,"_",D29,"_",E29) -> SAM_SalesTeam2_Digital Marketing Specialist | R29: =VLOOKUP(Q29,Roles!$A$2:$B$300,2,FALSE) -> 26
A30: C0000029 | B30: Engineering | C30: ENGG | D30: EngineeringTeam8 | E30: Engineering Manager | F30: Engineering Manager | G30: {=_xlfn.SWITCH(C30, "SAM", "Salesforce", "ITES","Jira", "ENGG","Python", "RND","Microsoft Platforms")} -> Python | H30: =VLOOKUP(E30,Roles!$C$1:$D$197,2,FALSE) -> 7 | I30: 45921 | J30: Carol Prince | K30: 45990 | N30: Internal | P30: Interviewing | Q30: =CONCATENATE(C30,"_",D30,"_",E30) -> ENGG_EngineeringTeam8_Engineering Manager | R30: =VLOOKUP(Q30,Roles!$A$2:$B$300,2,FALSE) -> 27
A31: C0000030 | B31: Research | C31: RND | D31: ResearchTeam3 | E31: Research Analyst | F31: Research Analyst | G31: {=_xlfn.SWITCH(C31, "SAM", "Salesforce", "ITES","Jira", "ENGG","Python", "RND","Microsoft Platforms")} -> Microsoft Platforms | H31: =VLOOKUP(E31,Roles!$C$1:$D$197,2,FALSE) -> 11 | I31: 45814 | J31: Ben Rogers | K31: 45860 | N31: Internal | P31: Interviewing | Q31: =CONCATENATE(C31,"_",D31,"_",E31) -> RND_ResearchTeam3_Research Analyst | R31: =VLOOKUP(Q31,Roles!$A$2:$B$300,2,FALSE) -> 22
A32: C0000031 | B32: Engineering | C32: ENGG | D32: EngineeringTeam1 | E32: Engineering Manager | F32: Engineering Manager | G32: {=_xlfn.SWITCH(C32, "SAM", "Salesforce", "ITES","Jira", "ENGG","Python", "RND","Microsoft Platforms")} -> Python | H32: =VLOOKUP(E32,Roles!$C$1:$D$197,2,FALSE) -> 7 | I32: 45869 | J32: Bruce Khan | K32: 45934 | N32: Internal | P32: Interviewing | Q32: =CONCATENATE(C32,"_",D32,"_",E32) -> ENGG_EngineeringTeam1_Engineering Manager | R32: =VLOOKUP(Q32,Roles!$A$2:$B$300,2,FALSE) -> 28
A33: C0000032 | B33: IT and Support | C33: ITES | D33: ITTeam7 | E33: System Administrator | F33: System Administrator | G33: {=_xlfn.SWITCH(C33, "SAM", "Salesforce", "ITES","Jira", "ENGG","Python", "RND","Microsoft Platforms")} -> Jira | H33: =VLOOKUP(E33,Roles!$C$1:$D$197,2,FALSE) -> 9 | I33: 45925 | J33: Selina Kyle | K33: 45970 | N33: Internal | P33: Interviewing | Q33: =CONCATENATE(C33,"_",D33,"_",E33) -> ITES_ITTeam7_System Administrator | R33: =VLOOKUP(Q33,Roles!$A$2:$B$300,2,FALSE) -> 29
A34: C0000033 | B34: IT and Support | C34: ITES | D34: ITTeam7 | E34: Computer Technician | F34: Computer Technician | G34: {=_xlfn.SWITCH(C34, "SAM", "Salesforce", "ITES","Jira", "ENGG","Python", "RND","Microsoft Platforms")} -> Jira | H34: =VLOOKUP(E34,Roles!$C$1:$D$197,2,FALSE) -> 10 | I34: 45892 | J34: Logan Cage | K34: 45962 | L34: 45981 | M34: 46044 | N34: Internal | O34: 1 | P34: Offered | Q34: =CONCATENATE(C34,"_",D34,"_",E34) -> ITES_ITTeam7_Computer Technician | R34: =VLOOKUP(Q34,Roles!$A$2:$B$300,2,FALSE) -> 30
A35: C0000034 | B35: Engineering | C35: ENGG | D35: EngineeringTeam2 | E35: VP Engineering | F35: VP Engineering | G35: {=_xlfn.SWITCH(C35, "SAM", "Salesforce", "ITES","Jira", "ENGG","Python", "RND","Microsoft Platforms")} -> Python | H35: =VLOOKUP(E35,Roles!$C$1:$D$197,2,FALSE) -> 3 | I35: 45829 | J35: Matt Howlett | K35: 45881 | N35: Internal | P35: Interviewing | Q35: =CONCATENATE(C35,"_",D35,"_",E35) -> ENGG_EngineeringTeam2_VP Engineering | R35: =VLOOKUP(Q35,Roles!$A$2:$B$300,2,FALSE) -> 31
A36: C0000035 | B36: Sales and Marketing | C36: SAM | D36: SalesTeam1 | E36: Brand Manager | F36: Brand Manager | G36: {=_xlfn.SWITCH(C36, "SAM", "Salesforce", "ITES","Jira", "ENGG","Python", "RND","Microsoft Platforms")} -> Salesforce | H36: =VLOOKUP(E36,Roles!$C$1:$D$197,2,FALSE) -> 7 | I36: 45863 | J36: Arthur Richards | K36: 45930 | N36: Internal | P36: Interviewing | Q36: =CONCATENATE(C36,"_",D36,"_",E36) -> SAM_SalesTeam1_Brand Manager | R36: =VLOOKUP(Q36,Roles!$A$2:$B$300,2,FALSE) -> 32
A37: C0000036 | B37: Engineering | C37: ENGG | D37: EngineeringTeam7 | E37: Senior SDE | F37: Senior SDE | G37: {=_xlfn.SWITCH(C37, "SAM", "Salesforce", "ITES","Jira", "ENGG","Python", "RND","Microsoft Platforms")} -> Python | H37: =VLOOKUP(E37,Roles!$C$1:$D$197,2,FALSE) -> 9 | I37: 45836 | J37: Arthur Jordan | K37: 45889 | N37: Internal | P37: Interviewing | Q37: =CONCATENATE(C37,"_",D37,"_",E37) -> ENGG_EngineeringTeam7_Senior SDE | R37: =VLOOKUP(Q37,Roles!$A$2:$B$300,2,FALSE) -> 33
A38: C0000037 | B38: Engineering | C38: ENGG | D38: EngineeringTeam3 | E38: Software Developer 1 | F38: Software Developer 1 | G38: {=_xlfn.SWITCH(C38, "SAM", "Salesforce", "ITES","Jira", "ENGG","Python", "RND","Microsoft Platforms")} -> Python | H38: =VLOOKUP(E38,Roles!$C$1:$D$197,2,FALSE) -> 11 | I38: 45885 | J38: Bucky Bishop | K38: 45931 | L38: 45950 | M38: 46008 | N38: Internal | O38: 2 | P38: Offered | Q38: =CONCATENATE(C38,"_",D38,"_",E38) -> ENGG_EngineeringTeam3_Software Developer 1 | R38: =VLOOKUP(Q38,Roles!$A$2:$B$300,2,FALSE) -> 34
A39: C0000038 | B39: Engineering | C39: ENGG | D39: EngineeringTeam1 | E39: Engineering Manager | F39: Engineering Manager | G39: {=_xlfn.SWITCH(C39, "SAM", "Salesforce", "ITES","Jira", "ENGG","Python", "RND","Microsoft Platforms")} -> Python | H39: =VLOOKUP(E39,Roles!$C$1:$D$197,2,FALSE) -> 7 | I39: 45849 | J39: Danny Rogers | K39: 45916 | L39: 45926 | M39: 46004 | N39: Internal | O39: 2 | P39: Offered | Q39: =CONCATENATE(C39,"_",D39,"_",E39) -> ENGG_EngineeringTeam1_Engineering Manager | R39: =VLOOKUP(Q39,Roles!$A$2:$B$300,2,FALSE) -> 28
A40: C0000039 | B40: Sales and Marketing | C40: SAM | D40: SalesTeam5 | E40: Sales Director | F40: Sales Director | G40: {=_xlfn.SWITCH(C40, "SAM", "Salesforce", "ITES","Jira", "ENGG","Python", "RND","Microsoft Platforms")} -> Salesforce | H40: =VLOOKUP(E40,Roles!$C$1:$D$197,2,FALSE) -> 4 | I40: 45809 | J40: Ben Barnes | K40: 45859 | N40: Internal | P40: Interviewing | Q40: =CONCATENATE(C40,"_",D40,"_",E40) -> SAM_SalesTeam5_Sales Director | R40: =VLOOKUP(Q40,Roles!$A$2:$B$300,2,FALSE) -> 11
...

Sheet Raw Data Final
A1: Role ID | B1: Role | C1: Stream | D1: Demand Date | E1: Date Job Requirement Released | F1: Date Offered | G1: Date Onboarded | H1: Internal/External | I1: Pipeline Updated | J1: Time to Offer | K1: Time to Onboard
A2: =Table1[[#This Row],[Role ID]] -> 1 | B2: =Table1[[#This Row],[Role]] -> Brand Manager | C2: =Table1[[#This Row],[Stream Internal]] -> SAM | D2: =IF(ISBLANK(Table1[[#This Row],[Demand Date]]),"",Table1[[#This Row],[Demand Date]]) -> 45878 | E2: =IF(ISBLANK(Table1[[#This Row],[Date Job Requirement Released]]),"",Table1[[#This Row],[Date Job Requirement Released]]) -> 45928 | F2: =IF(ISBLANK(Table1[[#This Row],[Date Offered]]),"",Table1[[#This Row],[Date Offered]]) | G2: =IF(ISBLANK(Table1[[#This Row],[Date Onboarded]]),"",Table1[[#This Row],[Date Onboarded]]) | H2: =Table1[[#This Row],[Internal/External]] -> Internal | I2: =Table1[[#This Row],[Pipeline Updated]] -> 0 | J2: =IF(OR(E2="",F2=""),"",F2-E2) | K2: =IF(OR(E2="",G2=""),"",G2-E2)
A3: =Table1[[#This Row],[Role ID]] -> 2 | B3: =Table1[[#This Row],[Role]] -> System Administrator | C3: =Table1[[#This Row],[Stream Internal]] -> ITES | D3: =IF(ISBLANK(Table1[[#This Row],[Demand Date]]),"",Table1[[#This Row],[Demand Date]]) -> 45891 | E3: =IF(ISBLANK(Table1[[#This Row],[Date Job Requirement Released]]),"",Table1[[#This Row],[Date Job Requirement Released]]) -> 45947 | F3: =IF(ISBLANK(Table1[[#This Row],[Date Offered]]),"",Table1[[#This Row],[Date Offered]]) -> 45962 | G3: =IF(ISBLANK(Table1[[#This Row],[Date Onboarded]]),"",Table1[[#This Row],[Date Onboarded]]) -> 45975 | H3: =Table1[[#This Row],[Internal/External]] -> Internal | I3: =Table1[[#This Row],[Pipeline Updated]] -> 2 | J3: =IF(OR(E3="",F3=""),"",F3-E3) -> 15 | K3: =IF(OR(E3="",G3=""),"",G3-E3) -> 28
A4: =Table1[[#This Row],[Role ID]] -> 3 | B4: =Table1[[#This Row],[Role]] -> IT Support Specialist | C4: =Table1[[#This Row],[Stream Internal]] -> ITES | D4: =IF(ISBLANK(Table1[[#This Row],[Demand Date]]),"",Table1[[#This Row],[Demand Date]]) -> 45901 | E4: =IF(ISBLANK(Table1[[#This Row],[Date Job Requirement Released]]),"",Table1[[#This Row],[Date Job Requirement Released]]) -> 45972 | F4: =IF(ISBLANK(Table1[[#This Row],[Date Offered]]),"",Table1[[#This Row],[Date Offered]]) | G4: =IF(ISBLANK(Table1[[#This Row],[Date Onboarded]]),"",Table1[[#This Row],[Date Onboarded]]) | H4: =Table1[[#This Row],[Internal/External]] -> Internal | I4: =Table1[[#This Row],[Pipeline Updated]] -> 0 | J4: =IF(OR(E4="",F4=""),"",F4-E4) | K4: =IF(OR(E4="",G4=""),"",G4-E4)
A5: =Table1[[#This Row],[Role ID]] -> 4 | B5: =Table1[[#This Row],[Role]] -> Sales Director | C5: =Table1[[#This Row],[Stream Internal]] -> SAM | D5: =IF(ISBLANK(Table1[[#This Row],[Demand Date]]),"",Table1[[#This Row],[Demand Date]]) -> 45889 | E5: =IF(ISBLANK(Table1[[#This Row],[Date Job Requirement Released]]),"",Table1[[#This Row],[Date Job Requirement Released]]) -> 45963 | F5: =IF(ISBLANK(Table1[[#This Row],[Date Offered]]),"",Table1[[#This Row],[Date Offered]]) | G5: =IF(ISBLANK(Table1[[#This Row],[Date Onboarded]]),"",Table1[[#This Row],[Date Onboarded]]) | H5: =Table1[[#This Row],[Internal/External]] -> Internal | I5: =Table1[[#This Row],[Pipeline Updated]] -> 0 | J5: =IF(OR(E5="",F5=""),"",F5-E5) | K5: =IF(OR(E5="",G5=""),"",G5-E5)
A6: =Table1[[#This Row],[Role ID]] -> 5 | B6: =Table1[[#This Row],[Role]] -> Platform Delivery Lead | C6: =Table1[[#This Row],[Stream Internal]] -> ENGG | D6: =IF(ISBLANK(Table1[[#This Row],[Demand Date]]),"",Table1[[#This Row],[Demand Date]]) -> 45881 | E6: =IF(ISBLANK(Table1[[#This Row],[Date Job Requirement Released]]),"",Table1[[#This Row],[Date Job Requirement Released]]) -> 45931 | F6: =IF(ISBLANK(Table1[[#This Row],[Date Offered]]),"",Table1[[#This Row],[Date Offered]]) | G6: =IF(ISBLANK(Table1[[#This Row],[Date Onboarded]]),"",Table1[[#This Row],[Date Onboarded]]) | H6: =Table1[[#This Row],[Internal/External]] -> Internal | I6: =Table1[[#This Row],[Pipeline Updated]] -> 0 | J6: =IF(OR(E6="",F6=""),"",F6-E6) | K6: =IF(OR(E6="",G6=""),"",G6-E6)
A7: =Table1[[#This Row],[Role ID]] -> 6 | B7: =Table1[[#This Row],[Role]] -> Staff Engineer | C7: =Table1[[#This Row],[Stream Internal]] -> ENGG | D7: =IF(ISBLANK(Table1[[#This Row],[Demand Date]]),"",Table1[[#This Row],[Demand Date]]) -> 45926 | E7: =IF(ISBLANK(Table1[[#This Row],[Date Job Requirement Released]]),"",Table1[[#This Row],[Date Job Requirement Released]]) -> 45990 | F7: =IF(ISBLANK(Table1[[#This Row],[Date Offered]]),"",Table1[[#This Row],[Date Offered]]) | G7: =IF(ISBLANK(Table1[[#This Row],[Date Onboarded]]),"",Table1[[#This Row],[Date Onboarded]]) | H7: =Table1[[#This Row],[Internal/External]] -> Internal | I7: =Table1[[#This Row],[Pipeline Updated]] -> 0 | J7: =IF(OR(E7="",F7=""),"",F7-E7) | K7: =IF(OR(E7="",G7=""),"",G7-E7)
A8: =Table1[[#This Row],[Role ID]] -> 7 | B8: =Table1[[#This Row],[Role]] -> Network Administrator | C8: =Table1[[#This Row],[Stream Internal]] -> ITES | D8: =IF(ISBLANK(Table1[[#This Row],[Demand Date]]),"",Table1[[#This Row],[Demand Date]]) -> 45856 | E8: =IF(ISBLANK(Table1[[#This Row],[Date Job Requirement Released]]),"",Table1[[#This Row],[Date Job Requirement Released]]) -> 45910 | F8: =IF(ISBLANK(Table1[[#This Row],[Date Offered]]),"",Table1[[#This Row],[Date Offered]]) -> 45925 | G8: =IF(ISBLANK(Table1[[#This Row],[Date Onboarded]]),"",Table1[[#This Row],[Date Onboarded]]) -> 45958 | H8: =Table1[[#This Row],[Internal/External]] -> Internal | I8: =Table1[[#This Row],[Pipeline Updated]] -> 0 | J8: =IF(OR(E8="",F8=""),"",F8-E8) -> 15 | K8: =IF(OR(E8="",G8=""),"",G8-E8) -> 48
A9: =Table1[[#This Row],[Role ID]] -> 8 | B9: =Table1[[#This Row],[Role]] -> System Administrator | C9: =Table1[[#This Row],[Stream Internal]] -> ITES | D9: =IF(ISBLANK(Table1[[#This Row],[Demand Date]]),"",Table1[[#This Row],[Demand Date]]) -> 45834 | E9: =IF(ISBLANK(Table1[[#This Row],[Date Job Requirement Released]]),"",Table1[[#This Row],[Date Job Requirement Released]]) -> 45900 | F9: =IF(ISBLANK(Table1[[#This Row],[Date Offered]]),"",Table1[[#This Row],[Date Offered]]) -> 45912 | G9: =IF(ISBLANK(Table1[[#This Row],[Date Onboarded]]),"",Table1[[#This Row],[Date Onboarded]]) -> 45999 | H9: =Table1[[#This Row],[Internal/External]] -> Internal | I9: =Table1[[#This Row],[Pipeline Updated]] -> 0 | J9: =IF(OR(E9="",F9=""),"",F9-E9) -> 12 | K9: =IF(OR(E9="",G9=""),"",G9-E9) -> 99
A10: =Table1[[#This Row],[Role ID]] -> 9 | B10: =Table1[[#This Row],[Role]] -> Software Developer 1 | C10: =Table1[[#This Row],[Stream Internal]] -> ENGG | D10: =IF(ISBLANK(Table1[[#This Row],[Demand Date]]),"",Table1[[#This Row],[Demand Date]]) -> 45864 | E10: =IF(ISBLANK(Table1[[#This Row],[Date Job Requirement Released]]),"",Table1[[#This Row],[Date Job Requirement Released]]) -> 45931 | F10: =IF(ISBLANK(Table1[[#This Row],[Date Offered]]),"",Table1[[#This Row],[Date Offered]]) -> 45946 | G10: =IF(ISBLANK(Table1[[#This Row],[Date Onboarded]]),"",Table1[[#This Row],[Date Onboarded]]) -> 45972 | H10: =Table1[[#This Row],[Internal/External]] -> Internal | I10: =Table1[[#This Row],[Pipeline Updated]] -> 2 | J10: =IF(OR(E10="",F10=""),"",F10-E10) -> 15 | K10: =IF(OR(E10="",G10=""),"",G10-E10) -> 41
A11: =Table1[[#This Row],[Role ID]] -> 10 | B11: =Table1[[#This Row],[Role]] -> Sales Director | C11: =Table1[[#This Row],[Stream Internal]] -> SAM | D11: =IF(ISBLANK(Table1[[#This Row],[Demand Date]]),"",Table1[[#This Row],[Demand Date]]) -> 45904 | E11: =IF(ISBLANK(Table1[[#This Row],[Date Job Requirement Released]]),"",Table1[[#This Row],[Date Job Requirement Released]]) -> 45959 | F11: =IF(ISBLANK(Table1[[#This Row],[Date Offered]]),"",Table1[[#This Row],[Date Offered]]) -> 45975 | G11: =IF(ISBLANK(Table1[[#This Row],[Date Onboarded]]),"",Table1[[#This Row],[Date Onboarded]]) -> 46007 | H11: =Table1[[#This Row],[Internal/External]] -> Internal | I11: =Table1[[#This Row],[Pipeline Updated]] -> 2 | J11: =IF(OR(E11="",F11=""),"",F11-E11) -> 16 | K11: =IF(OR(E11="",G11=""),"",G11-E11) -> 48
A12: =Table1[[#This Row],[Role ID]] -> 11 | B12: =Table1[[#This Row],[Role]] -> Sales Director | C12: =Table1[[#This Row],[Stream Internal]] -> SAM | D12: =IF(ISBLANK(Table1[[#This Row],[Demand Date]]),"",Table1[[#This Row],[Demand Date]]) -> 45872 | E12: =IF(ISBLANK(Table1[[#This Row],[Date Job Requirement Released]]),"",Table1[[#This Row],[Date Job Requirement Released]]) -> 45942 | F12: =IF(ISBLANK(Table1[[#This Row],[Date Offered]]),"",Table1[[#This Row],[Date Offered]]) -> 45955 | G12: =IF(ISBLANK(Table1[[#This Row],[Date Onboarded]]),"",Table1[[#This Row],[Date Onboarded]]) -> 46016 | H12: =Table1[[#This Row],[Internal/External]] -> Internal | I12: =Table1[[#This Row],[Pipeline Updated]] -> 0 | J12: =IF(OR(E12="",F12=""),"",F12-E12) -> 13 | K12: =IF(OR(E12="",G12=""),"",G12-E12) -> 74
A13: =Table1[[#This Row],[Role ID]] -> 12 | B13: =Table1[[#This Row],[Role]] -> System Administrator | C13: =Table1[[#This Row],[Stream Internal]] -> ITES | D13: =IF(ISBLANK(Table1[[#This Row],[Demand Date]]),"",Table1[[#This Row],[Demand Date]]) -> 45927 | E13: =IF(ISBLANK(Table1[[#This Row],[Date Job Requirement Released]]),"",Table1[[#This Row],[Date Job Requirement Released]]) -> 45994 | F13: =IF(ISBLANK(Table1[[#This Row],[Date Offered]]),"",Table1[[#This Row],[Date Offered]]) | G13: =IF(ISBLANK(Table1[[#This Row],[Date Onboarded]]),"",Table1[[#This Row],[Date Onboarded]]) | H13: =Table1[[#This Row],[Internal/External]] -> Internal | I13: =Table1[[#This Row],[Pipeline Updated]] -> 0 | J13: =IF(OR(E13="",F13=""),"",F13-E13) | K13: =IF(OR(E13="",G13=""),"",G13-E13)
... A301: =Table1[[#This Row],[Role ID]] -> 196 | B301: =Table1[[#This Row],[Role]] -> Computer Technician | C301: =Table1[[#This Row],[Stream Internal]] -> ITES | D301: =IF(ISBLANK(Table1[[#This Row],[Demand Date]]),"",Table1[[#This Row],[Demand Date]]) -> 45885 | E301: =IF(ISBLANK(Table1[[#This Row],[Date Job Requirement Released]]),"",Table1[[#This Row],[Date Job Requirement Released]]) -> 45944 | F301: =IF(ISBLANK(Table1[[#This Row],[Date Offered]]),"",Table1[[#This Row],[Date Offered]]) | G301: =IF(ISBLANK(Table1[[#This Row],[Date Onboarded]]),"",Table1[[#This Row],[Date Onboarded]]) | H301: =Table1[[#This Row],[Internal/External]] -> Internal | I301: =Table1[[#This Row],[Pipeline Updated]] -> 0 | J301: =IF(OR(E301="",F301=""),"",F301-E301) | K301: =IF(OR(E301="",G301=""),"",G301-E301)

Sheet Roles
A1: Role_IDP | B1: Role ID | C1: Role | D1: Role level | E1: Team | F1: Team ID | G1: Stream | H1: Stream ID
A2: {=_xlfn.UNIQUE(_xlfn._xlws.FILTER('Raw Data'!Q2:Q500, 'Raw Data'!Q2:Q500<>""))} -> SAM_SalesTeam4_Brand Manager | B2: {=_xlfn.SEQUENCE(COUNTA(_xlfn.ANCHORARRAY(A2)))} -> 1 | C2: {=_xlfn.TEXTAFTER(_xlfn.ANCHORARRAY(A2),"_",2)} -> Brand Manager | D2: 7 | E2: {=_xlfn.TEXTBEFORE(_xlfn.TEXTAFTER(_xlfn.ANCHORARRAY(A2),"_"),"_")} -> SalesTeam4 | F2: =VLOOKUP(E2,Teams!$A$1:$B$41,2,FALSE) -> 1 | G2: =_xlfn.TEXTBEFORE(A2,"_") -> SAM | H2: =VLOOKUP(G2,Streams!$C$1:$D$5,2,FALSE) -> 3
A3: ITES_ITTeam5_System Administrator | B3: 2 | C3: System Administrator | D3: 9 | E3: ITTeam5 | F3: =VLOOKUP(E3,Teams!$A$1:$B$41,2,FALSE) -> 2 | G3: =_xlfn.TEXTBEFORE(A3,"_") -> ITES | H3: =VLOOKUP(G3,Streams!$C$1:$D$5,2,FALSE) -> 2
A4: ITES_ITTeam5_IT Support Specialist | B4: 3 | C4: IT Support Specialist | D4: 9 | E4: ITTeam5 | F4: =VLOOKUP(E4,Teams!$A$1:$B$41,2,FALSE) -> 2 | G4: =_xlfn.TEXTBEFORE(A4,"_") -> ITES | H4: =VLOOKUP(G4,Streams!$C$1:$D$5,2,FALSE) -> 2
A5: SAM_SalesTeam4_Sales Director | B5: 4 | C5: Sales Director | D5: 4 | E5: SalesTeam4 | F5: =VLOOKUP(E5,Teams!$A$1:$B$41,2,FALSE) -> 1 | G5: =_xlfn.TEXTBEFORE(A5,"_") -> SAM | H5: =VLOOKUP(G5,Streams!$C$1:$D$5,2,FALSE) -> 3
A6: ENGG_EngineeringTeam1_Platform Delivery Lead | B6: 5 | C6: Platform Delivery Lead | D6: 5 | E6: EngineeringTeam1 | F6: =VLOOKUP(E6,Teams!$A$1:$B$41,2,FALSE) -> 3 | G6: =_xlfn.TEXTBEFORE(A6,"_") -> ENGG | H6: =VLOOKUP(G6,Streams!$C$1:$D$5,2,FALSE) -> 1
A7: ENGG_EngineeringTeam10_Staff Engineer | B7: 6 | C7: Staff Engineer | D7: 11 | E7: EngineeringTeam10 | F7: =VLOOKUP(E7,Teams!$A$1:$B$41,2,FALSE) -> 4 | G7: =_xlfn.TEXTBEFORE(A7,"_") -> ENGG | H7: =VLOOKUP(G7,Streams!$C$1:$D$5,2,FALSE) -> 1
A8: ITES_ITTeam2_Network Administrator | B8: 7 | C8: Network Administrator | D8: 9 | E8: ITTeam2 | F8: =VLOOKUP(E8,Teams!$A$1:$B$41,2,FALSE) -> 5 | G8: =_xlfn.TEXTBEFORE(A8,"_") -> ITES | H8: =VLOOKUP(G8,Streams!$C$1:$D$5,2,FALSE) -> 2
A9: ITES_ITTeam1_System Administrator | B9: 8 | C9: System Administrator | D9: 9 | E9: ITTeam1 | F9: =VLOOKUP(E9,Teams!$A$1:$B$41,2,FALSE) -> 6 | G9: =_xlfn.TEXTBEFORE(A9,"_") -> ITES | H9: =VLOOKUP(G9,Streams!$C$1:$D$5,2,FALSE) -> 2
A10: ENGG_EngineeringTeam1_Software Developer 1 | B10: 9 | C10: Software Developer 1 | D10: 11 | E10: EngineeringTeam1 | F10: =VLOOKUP(E10,Teams!$A$1:$B$41,2,FALSE) -> 3 | G10: =_xlfn.TEXTBEFORE(A10,"_") -> ENGG | H10: =VLOOKUP(G10,Streams!$C$1:$D$5,2,FALSE) -> 1
A11: SAM_SalesTeam3_Sales Director | B11: 10 | C11: Sales Director | D11: 4 | E11: SalesTeam3 | F11: =VLOOKUP(E11,Teams!$A$1:$B$41,2,FALSE) -> 7 | G11: =_xlfn.TEXTBEFORE(A11,"_") -> SAM | H11: =VLOOKUP(G11,Streams!$C$1:$D$5,2,FALSE) -> 3
A12: SAM_SalesTeam5_Sales Director | B12: 11 | C12: Sales Director | D12: 4 | E12: SalesTeam5 | F12: =VLOOKUP(E12,Teams!$A$1:$B$41,2,FALSE) -> 8 | G12: =_xlfn.TEXTBEFORE(A12,"_") -> SAM | H12: =VLOOKUP(G12,Streams!$C$1:$D$5,2,FALSE) -> 3
A13: ITES_ITTeam6_System Administrator | B13: 12 | C13: System Administrator | D13: 9 | E13: ITTeam6 | F13: =VLOOKUP(E13,Teams!$A$1:$B$41,2,FALSE) -> 9 | G13: =_xlfn.TEXTBEFORE(A13,"_") -> ITES | H13: =VLOOKUP(G13,Streams!$C$1:$D$5,2,FALSE) -> 2
A14: SAM_SalesTeam8_Digital Marketing Specialist | B14: 13 | C14: Digital Marketing Specialist | D14: 10 | E14: SalesTeam8 | F14: =VLOOKUP(E14,Teams!$A$1:$B$41,2,FALSE) -> 10 | G14: =_xlfn.TEXTBEFORE(A14,"_") -> SAM | H14: =VLOOKUP(G14,Streams!$C$1:$D$5,2,FALSE) -> 3
... A197: ITES_ITTeam10_Computer Technician | B197: 196 | C197: Computer Technician | D197: 10 | E197: ITTeam10 | F197: =VLOOKUP(E197,Teams!$A$1:$B$41,2,FALSE) -> 14 | G197: =_xlfn.TEXTBEFORE(A197,"_") -> ITES | H197: =VLOOKUP(G197,Streams!$C$1:$D$5,2,FALSE) -> 2

Sheet Teams
A1: Team | B1: Team ID
A2: {=_xlfn.UNIQUE(_xlfn._xlws.FILTER(_xlfn.ANCHORARRAY(Roles!E2),_xlfn.ANCHORARRAY(Roles!E2)<>""))} -> SalesTeam4 | B2: {=_xlfn.SEQUENCE(COUNTA(_xlfn.ANCHORARRAY(A2)))} -> 1
A3: ITTeam5 | B3: 2
A4: EngineeringTeam1 | B4: 3
A5: EngineeringTeam10 | B5: 4
A6: ITTeam2 | B6: 5
A7: ITTeam1 | B7: 6
A8: SalesTeam3 | B8: 7
A9: SalesTeam5 | B9: 8
A10: ITTeam6 | B10: 9
A11: SalesTeam8 | B11: 10
A12: ResearchTeam8 | B12: 11
A13: ITTeam9 | B13: 12
A14: ITTeam3 | B14: 13
... A41: SalesTeam9 | B41: 40

Sheet Streams
A1: Stream ID | B1: Stream | C1: Stream Code | D1: Stream ID_1
A2: 1 | B2: Engineering | C2: ENGG | D2: =A2 -> 1
A3: 2 | B3: IT and Support | C3: ITES | D3: =A3 -> 2
A4: 3 | B4: Sales and Marketing | C4: SAM | D4: =A4 -> 3
A5: 4 | B5: Research | C5: RND | D5: =A5 -> 4

Sheet Planned Demand
A1: Stream Code | B1: Team | C1: Role | D1: Year | E1: Quarter | F1: Month | G1: Planned Demand | H1: Month-SOW
A2: ENGG | B2: EngineeringTeam1 | C2: Engineering Manager | D2: 2025 | E2: ="Q"&ROUNDUP(MONTH(DATEVALUE(F2&" 1"))/3,0) -> Q3 | F2: July | G2: 1 | H2: =_xlfn.CONCAT(F2,"-",D2) -> July-2025
A3: ENGG | B3: EngineeringTeam1 | C3: Engineering Manager | D3: 2025 | E3: ="Q"&ROUNDUP(MONTH(DATEVALUE(F3&" 1"))/3,0) -> Q3 | F3: August | G3: 0 | H3: =_xlfn.CONCAT(F3,"-",D3) -> August-2025
A4: ENGG | B4: EngineeringTeam1 | C4: Engineering Manager | D4: 2025 | E4: ="Q"&ROUNDUP(MONTH(DATEVALUE(F4&" 1"))/3,0) -> Q3 | F4: September | G4: 0 | H4: =_xlfn.CONCAT(F4,"-",D4) -> September-2025
A5: ENGG | B5: EngineeringTeam1 | C5: Engineering Manager | D5: 2025 | E5: ="Q"&ROUNDUP(MONTH(DATEVALUE(F5&" 1"))/3,0) -> Q4 | F5: October | G5: 0 | H5: =_xlfn.CONCAT(F5,"-",D5) -> October-2025
A6: ENGG | B6: EngineeringTeam1 | C6: Engineering Manager | D6: 2025 | E6: ="Q"&ROUNDUP(MONTH(DATEVALUE(F6&" 1"))/3,0) -> Q4 | F6: November | G6: 0 | H6: =_xlfn.CONCAT(F6,"-",D6) -> November-2025
A7: ENGG | B7: EngineeringTeam1 | C7: Engineering Manager | D7: 2025 | E7: ="Q"&ROUNDUP(MONTH(DATEVALUE(F7&" 1"))/3,0) -> Q4 | F7: December | G7: 0 | H7: =_xlfn.CONCAT(F7,"-",D7) -> December-2025
A8: ENGG | B8: EngineeringTeam1 | C8: Engineering Manager | D8: 2026 | E8: ="Q"&ROUNDUP(MONTH(DATEVALUE(F8&" 1"))/3,0) -> Q1 | F8: January | G8: 0 | H8: =_xlfn.CONCAT(F8,"-",D8) -> January-2026
A9: ENGG | B9: EngineeringTeam1 | C9: Engineering Manager | D9: 2026 | E9: ="Q"&ROUNDUP(MONTH(DATEVALUE(F9&" 1"))/3,0) -> Q1 | F9: February | G9: 0 | H9: =_xlfn.CONCAT(F9,"-",D9) -> February-2026
A10: ENGG | B10: EngineeringTeam1 | C10: Engineering Manager | D10: 2026 | E10: ="Q"&ROUNDUP(MONTH(DATEVALUE(F10&" 1"))/3,0) -> Q1 | F10: March | G10: 0 | H10: =_xlfn.CONCAT(F10,"-",D10) -> March-2026
A11: ENGG | B11: EngineeringTeam1 | C11: Engineering Manager | D11: 2026 | E11: ="Q"&ROUNDUP(MONTH(DATEVALUE(F11&" 1"))/3,0) -> Q2 | F11: April | G11: 0 | H11: =_xlfn.CONCAT(F11,"-",D11) -> April-2026
A12: ENGG | B12: EngineeringTeam1 | C12: Engineering Manager | D12: 2026 | E12: ="Q"&ROUNDUP(MONTH(DATEVALUE(F12&" 1"))/3,0) -> Q2 | F12: May | G12: 0 | H12: =_xlfn.CONCAT(F12,"-",D12) -> May-2026
A13: ENGG | B13: EngineeringTeam1 | C13: Engineering Manager | D13: 2026 | E13: ="Q"&ROUNDUP(MONTH(DATEVALUE(F13&" 1"))/3,0) -> Q2 | F13: June | G13: 0 | H13: =_xlfn.CONCAT(F13,"-",D13) -> June-2026
... A1201: SAM | B1201: SalesTeam9 | C1201: Sales Director | D1201: 2026 | E1201: ="Q"&ROUNDUP(MONTH(DATEVALUE(F1201&" 1"))/3,0) -> Q2 | F1201: June | G1201: 0 | H1201: =_xlfn.CONCAT(F1201,"-",D1201) -> June-2026

Sheet Talent Data
A1: Year | B1: Quarter | C1: Month | D1: Date_Key | E1: Stream ID | F1: GallupQ score | G1: Employee Onboarding Experience | H1: ACE recognition % | I1: Client Recognition | J1: Time spent upskilling (hrs) | K1: Skill Proficiency Level - Not Assessed & <P1 (%) | L1: Skill Proficiency Level P1&P2 | M1: Skill Proficiency Level P3+ | N1: Industry Proficiency % | O1: Tech Profienciency % | P1: Other Proficiency % | Q1: Attrition % | R1: Retention % | S1: Ethics & Compliance Trainings | T1: Notice Period | U1: Functional Orientation HC | V1: FO Completion | W1: HCI | X1: HCI Responses | Y1: Feedback
A2: 2025 | B2: ="Q"&ROUNDUP(MONTH(DATEVALUE(C2&" 1"))/3,0) -> Q3 | C2: July | D2: =CONCATENATE(A2,"_",B2,"_",C2) -> 2025_Q3_July | E2: 1 | F2: 4.2 | G2: 0.98 | H2: 1 | I2: 3 | J2: 248 | K2: 0.28125 | L2: 0.0625 | M2: 0.65625 | N2: 0.168357 | O2: 0.70588235 | P2: 0.12576065 | Q2: 0 | R2: 1 | S2: 0.5 | T2: 0 | U2: 53 | V2: 32 | W2: 89 | X2: 127 | Y2: Excellent, Exciting, The Best, Roaring successful event, Useful, Engaging, Good, Awesome, Amazing, Very Good Experience, Surprising, Informative, Very well organized, Great Opportunity, Collaborative, Insightful, Vision oriented, Fun, Good to meet everyone, Great visibility, Energetic, Knowledge, Great Start, Innovative, Splendid, Innovative, Place to grow, Arrangements, Hope for success, Looking for more, Exceptional, Enthusiastic, Interactive, Clear direction
A3: 2025 | B3: ="Q"&ROUNDUP(MONTH(DATEVALUE(C3&" 1"))/3,0) -> Q3 | C3: July | D3: =CONCATENATE(A3,"_",B3,"_",C3) -> 2025_Q3_July | E3: 2 | F3: 4.36 | G3: 0.92 | H3: 0 | I3: 4 | J3: 440 | K3: 0.41891892 | L3: 0.10810811 | M3: 0.47297297 | N3: 0.20382166 | O3: 0.68789809 | P3: 0.10828025 | Q3: 1 | R3: 0 | S3: 0.8 | T3: 1 | U3: 74 | V3: 68 | W3: 46 | X3: 65 | Y3: Supercharged, Informative, Awesome, Knowledge, Core values, Great Session, client interaction, Vision, Super excited, Future growth, One Vertex, Deep dive, Insightful, Wonderful, Coordination, Exciting, One IT, Clarity, Innovation, Own the mission, Communication
A4: 2025 | B4: ="Q"&ROUNDUP(MONTH(DATEVALUE(C4&" 1"))/3,0) -> Q3 | C4: July | D4: =CONCATENATE(A4,"_",B4,"_",C4) -> 2025_Q3_July | E4: 3 | F4: 4.23 | G4: 0.9 | H4: 2 | I4: 5 | J4: 320 | K4: 0.28125 | L4: 0.0625 | M4: 0.65625 | N4: 0.168357 | O4: 0.70588235 | P4: 0.12576065 | Q4: 0 | R4: 0 | S4: 0.5 | T4: 0 | U4: 60 | V4: 49 | W4: 40 | X4: 51 | Y4: Excited, Clear Communication, Amazing, Engaging, Clear Direction, Importance of Innovation, Collaboration, Learning Opportunities, Good visibility, One Family
A5: 2025 | B5: ="Q"&ROUNDUP(MONTH(DATEVALUE(C5&" 1"))/3,0) -> Q3 | C5: July | D5: =CONCATENATE(A5,"_",B5,"_",C5) -> 2025_Q3_July | E5: 4 | F5: 4.1 | G5: 0.85 | H5: 1 | I5: 2 | J5: 328 | K5: 0.41891892 | L5: 0.10810811 | M5: 0.47297297 | N5: 0.20382166 | O5: 0.68789809 | P5: 0.10828025 | Q5: 0 | R5: 0 | S5: 0.8 | T5: 0 | U5: 100 | V5: 70 | W5: 48 | X5: 58 | Y5: Excellent, Exciting, The Best, Roaring successful event, Useful, Engaging, Good, Awesome, Amazing, Very Good Experience, Surprising, Informative, Very well organized, Great Opportunity, Collaborative, Insightful, Vision oriented, Fun, Good to meet everyone, Great visibility, Energetic, Knowledge, Great Start, Innovative, Splendid, Innovative, Place to grow, Arrangements, Hope for success, Looking for more, Exceptional, Enthusiastic, Interactive, Clear direction
A6: 2025 | B6: ="Q"&ROUNDUP(MONTH(DATEVALUE(C6&" 1"))/3,0) -> Q3 | C6: August | D6: =CONCATENATE(A6,"_",B6,"_",C6) -> 2025_Q3_August | E6: 1 | F6: 4.2 | G6: 0.98 | H6: 1 | I6: 3 | J6: 248 | K6: 0.28125 | L6: 0.0625 | M6: 0.65625 | N6: 0.168357 | O6: 0.70588235 | P6: 0.12576065 | Q6: 0 | R6: 1 | S6: 0.5 | T6: 0 | U6: 53 | V6: 32 | W6: 89 | X6: 127 | Y6: Excellent, Exciting, The Best, Roaring successful event, Useful, Engaging, Good, Awesome, Amazing, Very Good Experience, Surprising, Informative, Very well organized, Great Opportunity, Collaborative, Insightful, Vision oriented, Fun, Good to meet everyone, Great visibility, Energetic, Knowledge, Great Start, Innovative, Splendid, Innovative, Place to grow, Arrangements, Hope for success, Looking for more, Exceptional, Enthusiastic, Interactive, Clear direction
A7: 2025 | B7: ="Q"&ROUNDUP(MONTH(DATEVALUE(C7&" 1"))/3,0) -> Q3 | C7: August | D7: =CONCATENATE(A7,"_",B7,"_",C7) -> 2025_Q3_August | E7: 2 | F7: 4.36 | G7: 0.92 | H7: 0 | I7: 4 | J7: 440 | K7: 0.41891892 | L7: 0.10810811 | M7: 0.47297297 | N7: 0.20382166 | O7: 0.68789809 | P7: 0.10828025 | Q7: 1 | R7: 0 | S7: 0.8 | T7: 1 | U7: 74 | V7: 68 | W7: 46 | X7: 65 | Y7: Supercharged, Informative, Awesome, Knowledge, Core values, Great Session, client interaction, Vision, Super excited, Future growth, One Vertex, Deep dive, Insightful, Wonderful, Coordination, Exciting, One IT, Clarity, Innovation, Own the mission, Communication
A8: 2025 | B8: ="Q"&ROUNDUP(MONTH(DATEVALUE(C8&" 1"))/3,0) -> Q3 | C8: August | D8: =CONCATENATE(A8,"_",B8,"_",C8) -> 2025_Q3_August | E8: 3 | F8: 4.23 | G8: 0.9 | H8: 2 | I8: 5 | J8: 320 | K8: 0.28125 | L8: 0.0625 | M8: 0.65625 | N8: 0.168357 | O8: 0.70588235 | P8: 0.12576065 | Q8: 0 | R8: 0 | S8: 0.5 | T8: 0 | U8: 60 | V8: 49 | W8: 40 | X8: 51 | Y8: Excited, Clear Communication, Amazing, Engaging, Clear Direction, Importance of Innovation, Collaboration, Learning Opportunities, Good visibility, One Family
A9: 2025 | B9: ="Q"&ROUNDUP(MONTH(DATEVALUE(C9&" 1"))/3,0) -> Q3 | C9: August | D9: =CONCATENATE(A9,"_",B9,"_",C9) -> 2025_Q3_August | E9: 4 | F9: 4.1 | G9: 0.85 | H9: 1 | I9: 2 | J9: 328 | K9: 0.41891892 | L9: 0.10810811 | M9: 0.47297297 | N9: 0.20382166 | O9: 0.68789809 | P9: 0.10828025 | Q9: 0 | R9: 0 | S9: 0.8 | T9: 0 | U9: 100 | V9: 70 | W9: 48 | X9: 58 | Y9: Excellent, Exciting, The Best, Roaring successful event, Useful, Engaging, Good, Awesome, Amazing, Very Good Experience, Surprising, Informative, Very well organized, Great Opportunity, Collaborative, Insightful, Vision oriented, Fun, Good to meet everyone, Great visibility, Energetic, Knowledge, Great Start, Innovative, Splendid, Innovative, Place to grow, Arrangements, Hope for success, Looking for more, Exceptional, Enthusiastic, Interactive, Clear direction
A10: 2025 | B10: ="Q"&ROUNDUP(MONTH(DATEVALUE(C10&" 1"))/3,0) -> Q3 | C10: September | D10: =CONCATENATE(A10,"_",B10,"_",C10) -> 2025_Q3_September | E10: 1 | F10: 4.2 | G10: 0.98 | H10: 1 | I10: 3 | J10: 248 | K10: 0.28125 | L10: 0.0625 | M10: 0.65625 | N10: 0.168357 | O10: 0.70588235 | P10: 0.12576065 | Q10: 0 | R10: 1 | S10: 0.5 | T10: 0 | U10: 53 | V10: 32 | W10: 89 | X10: 127 | Y10: Excellent, Exciting, The Best, Roaring successful event, Useful, Engaging, Good, Awesome, Amazing, Very Good Experience, Surprising, Informative, Very well organized, Great Opportunity, Collaborative, Insightful, Vision oriented, Fun, Good to meet everyone, Great visibility, Energetic, Knowledge, Great Start, Innovative, Splendid, Innovative, Place to grow, Arrangements, Hope for success, Looking for more, Exceptional, Enthusiastic, Interactive, Clear direction
A11: 2025 | B11: ="Q"&ROUNDUP(MONTH(DATEVALUE(C11&" 1"))/3,0) -> Q3 | C11: September | D11: =CONCATENATE(A11,"_",B11,"_",C11) -> 2025_Q3_September | E11: 2 | F11: 4.36 | G11: 0.92 | H11: 0 | I11: 4 | J11: 440 | K11: 0.41891892 | L11: 0.10810811 | M11: 0.47297297 | N11: 0.20382166 | O11: 0.68789809 | P11: 0.10828025 | Q11: 1 | R11: 0 | S11: 0.8 | T11: 1 | U11: 74 | V11: 68 | W11: 46 | X11: 65 | Y11: Supercharged, Informative, Awesome, Knowledge, Core values, Great Session, client interaction, Vision, Super excited, Future growth, One Vertex, Deep dive, Insightful, Wonderful, Coordination, Exciting, One IT, Clarity, Innovation, Own the mission, Communication
A12: 2025 | B12: ="Q"&ROUNDUP(MONTH(DATEVALUE(C12&" 1"))/3,0) -> Q3 | C12: September | D12: =CONCATENATE(A12,"_",B12,"_",C12) -> 2025_Q3_September | E12: 3 | F12: 4.23 | G12: 0.9 | H12: 2 | I12: 5 | J12: 320 | K12: 0.28125 | L12: 0.0625 | M12: 0.65625 | N12: 0.168357 | O12: 0.70588235 | P12: 0.12576065 | Q12: 0 | R12: 0 | S12: 0.5 | T12: 0 | U12: 60 | V12: 49 | W12: 40 | X12: 51 | Y12: Excited, Clear Communication, Amazing, Engaging, Clear Direction, Importance of Innovation, Collaboration, Learning Opportunities, Good visibility, One Family
A13: 2025 | B13: ="Q"&ROUNDUP(MONTH(DATEVALUE(C13&" 1"))/3,0) -> Q3 | C13: September | D13: =CONCATENATE(A13,"_",B13,"_",C13) -> 2025_Q3_September | E13: 4 | F13: 4.1 | G13: 0.85 | H13: 1 | I13: 2 | J13: 328 | K13: 0.41891892 | L13: 0.10810811 | M13: 0.47297297 | N13: 0.20382166 | O13: 0.68789809 | P13: 0.10828025 | Q13: 0 | R13: 0 | S13: 0.8 | T13: 0 | U13: 100 | V13: 70 | W13: 48 | X13: 58 | Y13: Excellent, Exciting, The Best, Roaring successful event, Useful, Engaging, Good, Awesome, Amazing, Very Good Experience, Surprising, Informative, Very well organized, Great Opportunity, Collaborative, Insightful, Vision oriented, Fun, Good to meet everyone, Great visibility, Energetic, Knowledge, Great Start, Innovative, Splendid, Innovative, Place to grow, Arrangements, Hope for success, Looking for more, Exceptional, Enthusiastic, Interactive, Clear direction
... A17: 2025 | B17: ="Q"&ROUNDUP(MONTH(DATEVALUE(C17&" 1"))/3,0) -> Q4 | C17: October | D17: =CONCATENATE(A17,"_",B17,"_",C17) -> 2025_Q4_October | E17: 4 | F17: 4.1 | G17: 0.85 | H17: 1 | I17: 2 | J17: 328 | K17: 0.41891892 | L17: 0.10810811 | M17: 0.47297297 | N17: 0.20382166 | O17: 0.68789809 | P17: 0.10828025 | Q17: 0 | R17: 0 | S17: 0.8 | T17: 0 | U17: 100 | V17: 70 | W17: 48 | X17: 58 | Y17: Excellent, Exciting, The Best, Roaring successful event, Useful, Engaging, Good, Awesome, Amazing, Very Good Experience, Surprising, Informative, Very well organized, Great Opportunity, Collaborative, Insightful, Vision oriented, Fun, Good to meet everyone, Great visibility, Energetic, Knowledge, Great Start, Innovative, Splendid, Innovative, Place to grow, Arrangements, Hope for success, Looking for more, Exceptional, Enthusiastic, Interactive, Clear direction

Sheet Top Skills
A1: SkillName | B1: Function ID | C1: HC | D1: Month Number | E1: Year
A2: Data | B2: 1 | C2: 14 | D2: 10 | E2: 2025
A3: Microsoft Platform | B3: 1 | C3: 6 | D3: 10 | E3: 2025
A4: Java Technology Platform | B4: 1 | C4: 14 | D4: 10 | E4: 2025
A5: Agile | B5: 1 | C5: 1 | D5: 10 | E5: 2025
A6: Quality Engg | B6: 1 | C6: 5 | D6: 10 | E6: 2025
A7: Oracle | B7: 1 | C7: 2 | D7: 10 | E7: 2025
A8: DevOps | B8: 1 | C8: 4 | D8: 10 | E8: 2025
A9: CMT-Comms & Media | B9: 1 | C9: 1 | D9: 10 | E9: 2025
A10: Artificial Intelligence | B10: 1 | C10: 3 | D10: 10 | E10: 2025
A11: Arch Integration | B11: 1 | C11: 3 | D11: 10 | E11: 2025
A12: Cloud Operations | B12: 1 | C12: 2 | D12: 10 | E12: 2025
A13: APP | B13: 1 | C13: 1 | D13: 10 | E13: 2025
... A42: Market Intelligence | B42: 4 | C42: 10 | D42: 10 | E42: 2025

Sheet Health
E1: Formula | F1: =Actual ramp up/planned ramp up % | G1: =Average of % Completion of all teams (Story points completed vs. Story points committed in a sprint (%)) | H1: = Average employee satisfaction score/NPS | I1: =Average of quantitative score (1-5) shared per resource by functional PMO | J1: =Team wise integration score by functions
E2: Scale | F2: >90% - Yes <90% - No | G2: >90% - Yes <90% - No | H2: >50% - Yes <50% - No | I2: 4-5 - Yes 0-3 - No | J2: >80% - Yes <80% - No
E3: Weight | F3: 0.3 | G3: 0.3 | H3: 0.1 | I3: 0.2 | J3: 0.1
A4: Year | B4: Quarter | C4: Month | D4: Function ID | E4: Function | F4: Ramp-Up Progress | G4: Delivery Efficiency | H4: Employee Satisfaction | I4: Right Skill Acquisition | J4: Overall Integration with Organizational Framework and Culture | K4: Overall Score | L4: Weighted Score
A5: 2025 | B5: Q4 | C5: October | D5: 1 | E5: ENGG | F5: Yes | G5: Yes | H5: Yes | I5: Yes | J5: Yes | K5: =COUNTIF(F5:J5, "Yes") -> 5 | L5: =SUMIF(F5:J5,"Yes",$F$3:$J$3) -> 1
A6: 2025 | B6: Q4 | C6: October | D6: 2 | E6: ITES | F6: No | G6: Yes | H6: No | I6: Yes | J6: Yes | K6: =COUNTIF(F6:J6, "Yes") -> 3 | L6: =SUMIF(F6:J6,"Yes",$F$3:$J$3) -> 0.6
A7: 2025 | B7: Q4 | C7: October | D7: 3 | E7: SAM
A8: 2025 | B8: Q4 | C8: October | D8: 4 | E8: RND | F8: Yes | G8: Yes | H8: Yes | I8: Yes | J8: Yes | K8: =COUNTIF(F8:J8, "Yes") -> 5 | L8: =SUMIF(F8:J8,"Yes",$F$3:$J$3) -> 1

Sheet Program Data
A1: Control Tower | B1: Count of Tasks | C1: % Deviation | D1: Count Delayed | E1: Count on time | F1: Total Milestones | G1: Tower Name
A2: ENGG | B2: =COUNTIF('Program Deep Dive'!B:B,'Program Data'!A2) -> 14 | C2: =D2/B2 -> 0.071428571 | D2: =COUNTIFS('Program Deep Dive'!B:B,'Program Data'!A2,'Program Deep Dive'!G:G,"Late") -> 1 | E2: =B2-D2 -> 13 | F2: =SUMIF('Program Deep Dive'!B:B, 'Program Data'!A2,'Program Deep Dive'!H:H) -> 49 | G2: Product Engineering
A3: ITES | B3: =COUNTIF('Program Deep Dive'!B:B,'Program Data'!A3) -> 18 | C3: =D3/B3 -> 0.055555556 | D3: =COUNTIFS('Program Deep Dive'!B:B,'Program Data'!A3,'Program Deep Dive'!G:G,"Late") -> 1 | E3: =B3-D3 -> 17 | F3: =SUMIF('Program Deep Dive'!B:B, 'Program Data'!A3,'Program Deep Dive'!H:H) -> 61 | G3: IT & Enterprise Support
A4: SAM | B4: =COUNTIF('Program Deep Dive'!B:B,'Program Data'!A4) -> 18 | C4: =D4/B4 -> 0.22222222 | D4: =COUNTIFS('Program Deep Dive'!B:B,'Program Data'!A4,'Program Deep Dive'!G:G,"Late") -> 4 | E4: =B4-D4 -> 14 | F4: =SUMIF('Program Deep Dive'!B:B, 'Program Data'!A4,'Program Deep Dive'!H:H) -> 64 | G4: Sales & Marketing
A5: RND | B5: =COUNTIF('Program Deep Dive'!B:B,'Program Data'!A5) -> 16 | C5: =D5/B5 -> 0.1875 | D5: =COUNTIFS('Program Deep Dive'!B:B,'Program Data'!A5,'Program Deep Dive'!G:G,"Late") -> 3 | E5: =B5-D5 -> 13 | F5: =SUMIF('Program Deep Dive'!B:B, 'Program Data'!A5,'Program Deep Dive'!H:H) -> 55 | G5: Research & Development
A6: HRT | B6: =COUNTIF('Program Deep Dive'!B:B,'Program Data'!A6) -> 80 | C6: =D6/B6 -> 0.1625 | D6: =COUNTIFS('Program Deep Dive'!B:B,'Program Data'!A6,'Program Deep Dive'!G:G,"Late") -> 13 | E6: =B6-D6 -> 67 | F6: =SUMIF('Program Deep Dive'!B:B, 'Program Data'!A6,'Program Deep Dive'!H:H) -> 273 | G6: Human Resources & Talent
A7: VRO | B7: =COUNTIF('Program Deep Dive'!B:B,'Program Data'!A7) -> 45 | C7: =D7/B7 -> 0.022222222 | D7: =COUNTIFS('Program Deep Dive'!B:B,'Program Data'!A7,'Program Deep Dive'!G:G,"Late") -> 1 | E7: =B7-D7 -> 44 | F7: =SUMIF('Program Deep Dive'!B:B, 'Program Data'!A7,'Program Deep Dive'!H:H) -> 160 | G7: Value Realisation Office
A8: OCM | B8: =COUNTIF('Program Deep Dive'!B:B,'Program Data'!A8) -> 120 | C8: =D8/B8 -> 0.058333333 | D8: =COUNTIFS('Program Deep Dive'!B:B,'Program Data'!A8,'Program Deep Dive'!G:G,"Late") -> 7 | E8: =B8-D8 -> 113 | F8: =SUMIF('Program Deep Dive'!B:B, 'Program Data'!A8,'Program Deep Dive'!H:H) -> 426 | G8: Organizational Change Management

Sheet Program Deep Dive
A1: Serial ID | B1: Control Tower | C1: Stream | D1: Deliverable | E1: Completion | F1: Owner | G1: Status | H1: Milestones | I1: Task Start Date | J1: Planned End date | K1: Actual End Date
A2: 1.1.1 | B2: ENGG | C2: Group1 | D2: Task 1 of Group1 | E2: 0% Complete | G2: Not Late | H2: 3 | I2: 45932.721 | J2: 45985.451
A3: 1.1.13 | B3: ENGG | C3: Group1 | D3: Task 13 of Group1 | E3: 75% Complete | G3: Not Late | H3: 4 | I3: 45851.379 | J3: 45881.158 | K3: 45877.395
A4: 1.1.4 | B4: ENGG | C4: Group1 | D4: Task 4 of Group1 | E4: 50% Complete | G4: Late | H4: 4 | I4: 45844.085 | J4: 45864.933 | K4: 45868.342
A5: 1.1.5 | B5: ENGG | C5: Group1 | D5: Task 5 of Group1 | E5: 100% Complete | G5: Not Late | H5: 4 | I5: 45958.502 | J5: 45983.939
A6: 1.1.7 | B6: ENGG | C6: Group1 | D6: Task 7 of Group1 | E6: 50% Complete | G6: Not Late | H6: 4 | I6: 45912.102 | J6: 45934.908 | K6: 45937.121
A7: 1.1.8 | B7: ENGG | C7: Group1 | D7: Task 8 of Group1 | E7: 100% Complete | G7: Not Late | H7: 4 | I7: 45959.486 | J7: 45988.972
A8: 1.2.11 | B8: ENGG | C8: Group2 | D8: Task 11 of Group2 | E8: 50% Complete | G8: Not Late | H8: 4 | I8: 45964.531 | J8: 45992.176
A9: 1.2.14 | B9: ENGG | C9: Group2 | D9: Task 14 of Group2 | E9: 0% Complete | G9: Not Late | H9: 2 | I9: 45961.566 | J9: 45987.979
A10: 1.2.6 | B10: ENGG | C10: Group2 | D10: Task 6 of Group2 | E10: 50% Complete | G10: Not Late | H10: 4 | I10: 45849.263 | J10: 45875.979 | K10: 45877.758
A11: 1.2.9 | B11: ENGG | C11: Group2 | D11: Task 9 of Group2 | E11: 0% Complete | G11: Not Late | H11: 4 | I11: 45891.757 | J11: 45917.843 | K11: 45919.028
A12: 1.3.10 | B12: ENGG | C12: Group3 | D12: Task 10 of Group3 | E12: 50% Complete | G12: Not Late | H12: 3 | I12: 45857.018 | J12: 45873.056 | K12: 45865.48
A13: 1.3.12 | B13: ENGG | C13: Group3 | D13: Task 12 of Group3 | E13: 25% Complete | G13: Not Late | H13: 4 | I13: 45852.595 | J13: 45880.765 | K13: 45886.106
A14: 1.3.2 | B14: ENGG | C14: Group3 | D14: Task 2 of Group3 | E14: 100% Complete | G14: Not Late | H14: 1 | I14: 45899.717 | J14: 45919.054 | K14: 45912.959
A15: 1.3.3 | B15: ENGG | C15: Group3 | D15: Task 3 of Group3 | E15: 0% Complete | G15: Not Late | H15: 4 | I15: 45885.418 | J15: 45914.912 | K15: 45917.539
A16: 2.1.1 | B16: ITES | C16: Group1 | D16: Task 1 of Group1 | E16: 75% Complete | G16: Not Late | H16: 4 | I16: 45909.239 | J16: 45927.221 | K16: 45933.998
A17: 2.1.4 | B17: ITES | C17: Group1 | D17: Task 4 of Group1 | E17: 25% Complete | G17: Not Late | H17: 3 | I17: 45994.133 | J17: 46020.423
A18: 2.2.13 | B18: ITES | C18: Group2 | D18: Task 13 of Group2 | E18: 100% Complete | G18: Not Late | H18: 4 | I18: 45987.64 | J18: 46016.157
A19: 2.2.14 | B19: ITES | C19: Group2 | D19: Task 14 of Group2 | E19: 100% Complete | G19: Not Late | H19: 4 | I19: 45886.945 | J19: 45915.441 | K19: 45924.304
A20: 2.2.15 | B20: ITES | C20: Group2 | D20: Task 15 of Group2 | E20: 100% Complete | G20: Not Late | H20: 4 | I20: 45952.318 | J20: 45970.005
A21: 2.2.17 | B21: ITES | C21: Group2 | D21: Task 17 of Group2 | E21: 25% Complete | G21: Not Late | H21: 4 | I21: 45968.606 | J21: 45998.518
A22: 2.2.18 | B22: ITES | C22: Group2 | D22: Task 18 of Group2 | E22: 0% Complete | G22: Not Late | H22: 2 | I22: 45876.729 | J22: 45903.673 | K22: 45899.404
A23: 2.2.2 | B23: ITES | C23: Group2 | D23: Task 2 of Group2 | E23: 25% Complete | G23: Not Late | H23: 4 | I23: 45887.451 | J23: 45909.166 | K23: 45919.044
A24: 2.2.3 | B24: ITES | C24: Group2 | D24: Task 3 of Group2 | E24: 100% Complete | G24: Not Late | H24: 4 | I24: 45983.707 | J24: 46012.395
A25: 2.2.5 | B25: ITES | C25: Group2 | D25: Task 5 of Group2 | E25: 25% Complete | G25: Late | H25: 1 | I25: 45963.492 | J25: 45989.092
A26: 2.2.7 | B26: ITES | C26: Group2 | D26: Task 7 of Group2 | E26: 0% Complete | G26: Not Late | H26: 3 | I26: 45884.568 | J26: 45901.436 | K26: 45893.308
A27: 2.3.10 | B27: ITES | C27: Group3 | D27: Task 10 of Group3 | E27: 100% Complete | G27: Not Late | H27: 3 | I27: 45981.513 | J27: 46006.198
A28: 2.3.11 | B28: ITES | C28: Group3 | D28: Task 11 of Group3 | E28: 0% Complete | G28: Not Late | H28: 4 | I28: 45874.898 | J28: 45900.933 | K28: 45902.789
A29: 2.3.12 | B29: ITES | C29: Group3 | D29: Task 12 of Group3 | E29: 0% Complete | G29: Not Late | H29: 4 | I29: 46009.377 | J29: 46035.252
A30: 2.3.16 | B30: ITES | C30: Group3 | D30: Task 16 of Group3 | E30: 0% Complete | G30: Not Late | H30: 4 | I30: 45930.165 | J30: 45948.062 | K30: 45943.069
A31: 2.3.6 | B31: ITES | C31: Group3 | D31: Task 6 of Group3 | E31: 0% Complete | G31: Not Late | H31: 4 | I31: 46010.394 | J31: 46036.772
A32: 2.3.8 | B32: ITES | C32: Group3 | D32: Task 8 of Group3 | E32: 75% Complete | G32: Not Late | H32: 1 | I32: 45941.919 | J32: 45958.573 | K32: 45964.81
A33: 2.3.9 | B33: ITES | C33: Group3 | D33: Task 9 of Group3 | E33: 0% Complete | G33: Not Late | H33: 4 | I33: 45843.763 | J33: 45872.185 | K33: 45871.511
A34: 3.1.1 | B34: SAM | C34: Group1 | D34: Task 1 of Group1 | E34: 25% Complete | G34: Not Late | H34: 4 | I34: 45888.52 | J34: 45909.982 | K34: 45914.245
A35: 3.1.10 | B35: SAM | C35: Group1 | D35: Task 10 of Group1 | E35: 0% Complete | G35: Not Late | H35: 4 | I35: 45856.53 | J35: 45884.252 | K35: 45892.559
